<?xml version="1.0"?>
<robot name="rokisim_6dof_cobot">

  <link name="world"/>
  <joint name="fixed_to_world" type="fixed">
    <parent link="world"/>
    <child link="base_link"/>
    <origin xyz="0 0 0" rpy="0 0 0"/>
  </joint>

  <material name="dark_grey"><color rgba="0.2 0.2 0.2 1"/></material>
  <material name="kuka_orange"><color rgba="1.0 0.4 0.0 1"/></material>
  <material name="light_grey"><color rgba="0.7 0.7 0.7 1"/></material>

  <link name="base_link">
    <visual><origin xyz="0 0 0.025"/><geometry><cylinder radius="0.1" length="0.05"/></geometry><material name="dark_grey"/></visual>
    <collision><origin xyz="0 0 0.025"/><geometry><cylinder radius="0.1" length="0.05"/></geometry></collision>
    <inertial><mass value="5.0"/><inertia ixx="0.01" ixy="0" ixz="0" iyy="0.01" iyz="0" izz="0.01"/></inertial>
  </link>

  <link name="link1">
    <visual><origin xyz="0 0 0.1"/><geometry><cylinder radius="0.07" length="0.2"/></geometry><material name="kuka_orange"/></visual>
    <collision><origin xyz="0 0 0.1"/><geometry><cylinder radius="0.07" length="0.2"/></geometry></collision>
    <inertial><mass value="4.0"/><origin xyz="0 0 0.1"/><inertia ixx="0.01" ixy="0" ixz="0" iyy="0.01" iyz="0" izz="0.01"/></inertial>
  </link>
  <joint name="joint1" type="revolute">
    <parent link="base_link"/><child link="link1"/><origin xyz="0 0 0.05" rpy="0 0 0"/><axis xyz="0 0 1"/>
    <limit lower="-2.8" upper="2.8" effort="150" velocity="1.5"/>
  </joint>

  <link name="link2">
    <visual><origin xyz="0 0 0.2"/><geometry><cylinder radius="0.06" length="0.4"/></geometry><material name="light_grey"/></visual>
    <collision><origin xyz="0 0 0.2"/><geometry><cylinder radius="0.06" length="0.4"/></geometry></collision>
    <inertial><mass value="5.0"/><origin xyz="0 0 0.2"/><inertia ixx="0.02" ixy="0" ixz="0" iyy="0.02" iyz="0" izz="0.01"/></inertial>
  </link>
  <joint name="joint2" type="revolute">
    <parent link="link1"/><child link="link2"/><origin xyz="0 0 0.2" rpy="0 1.5708 0"/><axis xyz="0 1 0"/>
    <limit lower="-1.57" upper="1.57" effort="150" velocity="1.5"/>
  </joint>

  <link name="link3">
    <visual><origin xyz="0 0 0.15"/><geometry><cylinder radius="0.05" length="0.3"/></geometry><material name="kuka_orange"/></visual>
    <collision><origin xyz="0 0 0.15"/><geometry><cylinder radius="0.05" length="0.3"/></geometry></collision>
    <inertial><mass value="3.0"/><origin xyz="0 0 0.15"/><inertia ixx="0.01" ixy="0" ixz="0" iyy="0.01" iyz="0" izz="0.01"/></inertial>
  </link>
  <joint name="joint3" type="revolute">
    <parent link="link2"/><child link="link3"/><origin xyz="0 0 0.4" rpy="0 0 0"/><axis xyz="0 1 0"/>
    <limit lower="-2.45" upper="2.45" effort="150" velocity="2.0"/>
  </joint>

  <link name="link4">
    <visual><origin xyz="0 0 0.05"/><geometry><cylinder radius="0.04" length="0.1"/></geometry><material name="light_grey"/></visual>
    <collision><origin xyz="0 0 0.05"/><geometry><cylinder radius="0.04" length="0.1"/></geometry></collision>
    <inertial><mass value="1.0"/><origin xyz="0 0 0.05"/><inertia ixx="0.001" ixy="0" ixz="0" iyy="0.001" iyz="0" izz="0.001"/></inertial>
  </link>
  <joint name="joint4" type="revolute">
    <parent link="link3"/><child link="link4"/><origin xyz="0 0 0.3" rpy="0 0 0"/><axis xyz="1 0 0"/>
    <limit lower="-1.57" upper="1.57" effort="50" velocity="2.5"/>
  </joint>

  <link name="link5">
    <visual><origin xyz="0 0 0.05"/><geometry><cylinder radius="0.035" length="0.1"/></geometry><material name="kuka_orange"/></visual>
    <collision><origin xyz="0 0 0.05"/><geometry><cylinder radius="0.035" length="0.1"/></geometry></collision>
    <inertial><mass value="1.0"/><origin xyz="0 0 0.05"/><inertia ixx="0.001" ixy="0" ixz="0" iyy="0.001" iyz="0" izz="0.001"/></inertial>
  </link>
  <joint name="joint5" type="revolute">
    <parent link="link4"/><child link="link5"/><origin xyz="0 0 0.1" rpy="0 0 0"/><axis xyz="0 1 0"/>
    <limit lower="-3.14" upper="3.14" effort="50" velocity="3.15"/>
  </joint>

  <link name="link6">
    <visual><origin xyz="0 0 0.025"/><geometry><cylinder radius="0.03" length="0.05"/></geometry><material name="dark_grey"/></visual>
    <collision><origin xyz="0 0 0.025"/><geometry><cylinder radius="0.03" length="0.05"/></geometry></collision>
    <inertial><mass value="0.5"/><origin xyz="0 0 0.025"/><inertia ixx="0.001" ixy="0" ixz="0" iyy="0.001" iyz="0" izz="0.001"/></inertial>
  </link>
  <joint name="joint6" type="revolute">
    <parent link="link5"/><child link="link6"/><origin xyz="0 0 0.1" rpy="0 0 0"/><axis xyz="0 0 1"/>
    <limit lower="-3.14" upper="3.14" effort="50" velocity="3.15"/>
  </joint>

  <link name="gripper_base">
    <visual><origin xyz="0 0 0.02"/><geometry><box size="0.16 0.04 0.04"/></geometry><material name="dark_grey"/></visual>
    <collision><origin xyz="0 0 0.02"/><geometry><box size="0.16 0.04 0.04"/></geometry></collision>
    <inertial><mass value="0.2"/><inertia ixx="0.0002" ixy="0" ixz="0" iyy="0.0002" iyz="0" izz="0.0002"/></inertial>
  </link>
  <joint name="gripper_base_joint" type="fixed">
    <parent link="link6"/><child link="gripper_base"/><origin xyz="0 0 0.05" rpy="0 0 0"/>
  </joint>

  <link name="finger_right">
    <visual><origin xyz="0 0 0.05"/><geometry><box size="0.015 0.03 0.10"/></geometry><material name="kuka_orange"/></visual>
    <collision><origin xyz="0 0 0.05"/><geometry><box size="0.015 0.03 0.10"/></geometry></collision>
    <inertial><mass value="0.05"/><inertia ixx="0.00005" ixy="0" ixz="0" iyy="0.00005" iyz="0" izz="0.00005"/></inertial>
  </link>
  <joint name="gripper_right_joint" type="fixed"> 
    <parent link="gripper_base"/><child link="finger_right"/>
    <origin xyz="-0.07 0 0.04" rpy="0 0 0"/>
  </joint>

  <link name="finger_left">
    <visual><origin xyz="0 0 0.05"/><geometry><box size="0.015 0.03 0.10"/></geometry><material name="kuka_orange"/></visual>
    <collision><origin xyz="0 0 0.05"/><geometry><box size="0.015 0.03 0.10"/></geometry></collision>
    <inertial><mass value="0.05"/><inertia ixx="0.00005" ixy="0" ixz="0" iyy="0.00005" iyz="0" izz="0.00005"/></inertial>
  </link>
  <joint name="gripper_joint" type="prismatic"> <parent link="gripper_base"/><child link="finger_left"/>
    <origin xyz="0.07 0 0.04" rpy="0 0 0"/><axis xyz="-1 0 0"/> 
    <limit lower="0.0" upper="0.125" effort="100" velocity="0.5"/>
  </joint>

  <link name="camera_pivot"><inertial><mass value="0.01"/><inertia ixx="0.0001" ixy="0" ixz="0" iyy="0.0001" iyz="0" izz="0.0001"/></inertial></link>
  <joint name="camera_pan_joint" type="continuous"><parent link="world"/><child link="camera_pivot"/><origin xyz="0 0 0" rpy="0 0 0"/><axis xyz="0 0 1"/></joint>
  
  <link name="camera_link">
    <visual><geometry><box size="0.05 0.05 0.05"/></geometry><material name="dark_grey"/></visual>
    <inertial><mass value="0.1"/><origin xyz="0 0 0"/><inertia ixx="0.0001" ixy="0" ixz="0" iyy="0.0001" iyz="0" izz="0.0001"/></inertial>
  </link>
  <joint name="camera_mount_joint" type="fixed"><parent link="camera_pivot"/><child link="camera_link"/><origin xyz="1.5 0 1.2" rpy="0 0.5 3.14159"/></joint>

  <gazebo reference="camera_link">
    <sensor type="camera" name="kamera_sensor">
      <always_on>true</always_on><update_rate>30.0</update_rate>
      <camera name="kamera"><horizontal_fov>1.047</horizontal_fov><image><width>640</width><height>480</height><format>R8G8B8</format></image><clip><near>0.1</near><far>100</far></clip></camera>
      <plugin name="camera_controller" filename="libgazebo_ros_camera.so"><ros><namespace>kamera</namespace></ros><frame_name>camera_link</frame_name></plugin>
    </sensor>
  </gazebo>

  <ros2_control name="GazeboSystem" type="system">
    <hardware><plugin>gazebo_ros2_control/GazeboSystem</plugin></hardware>
    <joint name="joint1"><command_interface name="position"/><state_interface name="position"/></joint>
    <joint name="joint2"><command_interface name="position"/><state_interface name="position"/></joint>
    <joint name="joint3"><command_interface name="position"/><state_interface name="position"/></joint>
    <joint name="joint4"><command_interface name="position"/><state_interface name="position"/></joint>
    <joint name="joint5"><command_interface name="position"/><state_interface name="position"/></joint>
    <joint name="joint6"><command_interface name="position"/><state_interface name="position"/></joint>
    <joint name="gripper_joint"><command_interface name="position"/><state_interface name="position"/></joint>
    <joint name="camera_pan_joint"><command_interface name="position"/><state_interface name="position"/></joint>
  </ros2_control>

  <gazebo>
    <plugin name="gazebo_ros2_control" filename="libgazebo_ros2_control.so">
      <parameters>/home/main/rokisim_ws/src/rokisim_gazebo/config/controllers.yaml</parameters>
    </plugin>
  </gazebo>

  <gazebo reference="finger_left">
    <mu1>1000.0</mu1><mu2>1000.0</mu2><material>Gazebo/Orange</material>
  </gazebo>
  <gazebo reference="finger_right">
    <mu1>1000.0</mu1><mu2>1000.0</mu2><material>Gazebo/Orange</material>
  </gazebo>

  <gazebo reference="base_link"><material>Gazebo/DarkGrey</material></gazebo>
  <gazebo reference="link1"><material>Gazebo/Orange</material></gazebo>
  <gazebo reference="link2"><material>Gazebo/DarkGrey</material></gazebo>
  <gazebo reference="link3"><material>Gazebo/Orange</material></gazebo>
  <gazebo reference="link4"><material>Gazebo/DarkGrey</material></gazebo>
  <gazebo reference="link5"><material>Gazebo/Orange</material></gazebo>
  <gazebo reference="link6"><material>Gazebo/DarkGrey</material></gazebo>

</robot>